<?xml version="1.0" encoding="utf-8"?>
<?xml version="1.0" ?>


<robot name="pointmass">

<!-- 
	Base 
-->

  <link name="base">
    <visual>
      <origin rpy="0 0 0" xyz="0 0 0"/>
      <geometry>
	      <sphere radius="0.1"/>
	      <!-- [m] [m] [m] -->
      </geometry>
    </visual>
    <collision>
      <origin rpy="0 0 0" xyz="0 0 0"/>
      <geometry>
	      <sphere radius="0.1"/>
	      <!-- [m] [m] [m] -->
      </geometry>
    </collision>
  </link>

  <joint name="base_joint" type="fixed">
    <origin rpy="0 0 0" xyz="0 0 0"/>
    <parent link="base"/>
    <child link="base_inertia"/>
  </joint>

  <link name="base_inertia">
    <inertial>
      <origin xyz="0 0 0"/>
      <mass value="1"/>
      <inertia  ixx="0.016" ixy="0.0"  ixz="0.0"  iyy="0.016"  iyz="0.0"  izz="0.016" />
    </inertial>
  </link>



<!-- 
rotor 0: counter-clockwise 
-->
  
  <joint name="rotor_0_joint" type="continuous">
    <origin rpy="0 1.5708 0" xyz="0.1 0.0 0.0"/>
    <axis xyz="0 0 1"/>
    <limit effort="2000" velocity="838" />
    <parent link="base"/>
    <child link="rotor_0"/>
    <dynamics damping="0.0" friction="0.0"/>
  </joint>

  <link name="rotor_0">
    <inertial>
      <mass value="1e-6"/>
      <!-- [kg] -->
      <inertia ixx="1e-6" ixy="0.0" ixz="0.0" iyy="1e-6" iyz="0.0" izz="1e-6"/>
    </inertial>
    <visual>
      <geometry>
	      <mesh filename="../meshes/propeller_cw.dae" scale="0 0 0"/>
        <!-- The propeller meshes have a radius of 1m -->
	      <box size="0 0 0"/>
      </geometry>
    </visual>
    <collision>
      <geometry>
	      <cylinder length="0" radius="0"/>
        <!-- [m] -->
      </geometry>
    </collision>
  </link>

<!-- 
rotor 1: clockwise 
-->
  <joint name="rotor_1_joint" type="continuous">
    <origin rpy="-1.5708 0 0" xyz="0 0.1 0.0"/>
    <axis xyz="0 0 1"/>
    <limit effort="2000" velocity="838" />
    <parent link="base"/>
    <child link="rotor_1"/>
    <dynamics damping="0.0" friction="0.0"/>
  </joint>

  <link name="rotor_1">
    <inertial>
      <mass value="1e-6"/>
      <!-- [kg] -->
      <inertia ixx="1e-6" ixy="0.0" ixz="0.0" iyy="1e-6" iyz="0.0" izz="1e-6"/>
    </inertial>
    <visual>
      <geometry>
        <mesh filename="../meshes/propeller_cw.dae" scale="0 0 0"/>
        <!-- The propeller meshes have a radius of 1m -->
	      <box size="0 0 0"/>
      </geometry>
    </visual>
    <collision>
      <geometry>
	      <cylinder length="0" radius="0"/>
        <!-- [m] -->
      </geometry>
    </collision>
  </link>

<!-- 
rotor 2: counter-clockwise 
-->
  
  <joint name="rotor_2_joint" type="continuous">
    <origin rpy="0 -1.5708 0" xyz="-0.1 0.0 0.0"/>
    <axis xyz="0 0 1"/>
    <limit effort="2000" velocity="838" />
    <parent link="base"/>
    <child link="rotor_2"/>
    <dynamics damping="0.0" friction="0.0"/>
  </joint>

  <link name="rotor_2">
    <inertial>
      <mass value="1e-6"/>
      <!-- [kg] -->
      <inertia ixx="1e-6" ixy="0.0" ixz="0.0" iyy="1e-6" iyz="0.0" izz="1e-6"/>
    </inertial>
    <visual>
      <geometry>
        <mesh filename="../meshes/propeller_ccw.dae" scale="0 0 0"/>
        <!-- The propeller meshes have a radius of 1m -->
	      <box size="0 0 0"/>
      </geometry>
    </visual>
    <collision>
      <geometry>
	      <cylinder length="0" radius="0"/>
        <!-- [m] -->
      </geometry>
    </collision>
  </link>

<!-- 
rotor 3: clockwise 
-->
  <joint name="rotor_3_joint" type="continuous">
    <origin rpy="1.5708 0 0" xyz="0 -0.1 0.0"/>
    <axis xyz="0 0 1"/>
    <limit effort="2000" velocity="838" />
    <parent link="base"/>
    <child link="rotor_3"/>
    <dynamics damping="0.0" friction="0.0"/>
  </joint>

  <link name="rotor_3">
    <inertial>
      <mass value="1e-6"/>
      <!-- [kg] -->
      <inertia ixx="1e-6" ixy="0.0" ixz="0.0" iyy="1e-6" iyz="0.0" izz="1e-6"/>
    </inertial>
    <visual>
      <geometry>
        <mesh filename="../meshes/propeller_cw.dae" scale="0 0 0"/>
        <!-- The propeller meshes have a radius of 1m -->
	      <box size="0 0 0"/>
      </geometry>
    </visual>
    <collision>
      <geometry>
	      <cylinder length="0" radius="0"/>
        <!-- [m] -->
      </geometry>
    </collision>
  </link>

</robot>


